<sdf version='1.11'>
  <world name='car_world'>
    <physics name='1ms' type='ignored'>
      <max_step_size>0.001</max_step_size>
      <real_time_factor>1</real_time_factor>
      <real_time_update_rate>1000</real_time_update_rate>
    </physics>
    <plugin name='gz::sim::systems::Physics' filename='gz-sim-physics-system'/>
    <plugin name='gz::sim::systems::UserCommands' filename='gz-sim-user-commands-system'/>
    <plugin name='gz::sim::systems::SceneBroadcaster' filename='gz-sim-scene-broadcaster-system'/>
    <plugin name='gz::sim::systems::Sensors' filename='gz-sim-sensors-system'>
      <render_engine>ogre2</render_engine>
    </plugin>
    <plugin name='gz::sim::systems::Imu' filename='gz-sim-imu-system'/>

    <light name='sun' type='directional'>
      <cast_shadows>true</cast_shadows>
      <pose>0 0 10 0 0 0</pose>
      <diffuse>0.8 0.8 0.8 1</diffuse>
      <specular>0.2 0.2 0.2 1</specular>
      <attenuation>
        <range>1000</range>
        <constant>0.9</constant>
        <linear>0.01</linear>
        <quadratic>0.001</quadratic>
      </attenuation>
      <direction>-0.5 0.1 -0.9</direction>
    </light>

    <model name='nexus_robot' canonical_link='chassis'>
      <pose relative_to='world'>0 0 0.5 0 0 0</pose>

      <plugin name='gz::sim::systems::DiffDrive' filename='gz-sim-diff-drive-system'>
        <left_joint>left_wheel_joint</left_joint>
        <right_joint>right_wheel_joint</right_joint>
        <wheel_separation>0.1</wheel_separation>
        <wheel_radius>0.1</wheel_radius>
        <odom_publish_frequency>20</odom_publish_frequency>
        <topic>cmd_vel</topic>
        <odom_topic>odom</odom_topic>
      </plugin>

      <link name='chassis'>
        <pose relative_to='__model__'>0 0 0.05 0 0 0</pose>
        <inertial>
          <mass>5.0</mass>
          <inertia>
            <ixx>0.05</ixx><ixy>0</ixy><ixz>0</ixz>
            <iyy>0.06</iyy><iyz>0</iyz>
            <izz>0.08</izz>
          </inertia>
        </inertial>

        <visual name='visual'>
          <pose>0 0 -0.1 0 0 1.5708</pose>
          <geometry>
            <mesh>
              <uri>file:///home/prhayogo/Documents/Nexus_Gazebo/test_ukuran_base.stl</uri>
              <scale>1.1 1.1 1.1</scale>
            </mesh>
          </geometry>
          <material>
            <ambient>0.2 0.2 0.8 1</ambient>
            <diffuse>0.2 0.2 0.8 1</diffuse>
            <specular>0.1 0.1 0.1 1</specular>
          </material>
        </visual>

        <collision name='collision_mesh'>
          <pose>0 0 -0.1 0 0 1.5708</pose>
          <geometry>
            <mesh>
              <uri>file:///home/prhayogo/Documents/Nexus_Gazebo/test_ukuran_base.stl</uri>
              <scale>1 1 1</scale>
            </mesh>
          </geometry>
        </collision>

        <!-- IMU Sensor -->
        <sensor name='imu_sensor' type='imu'>
          <pose>0 0 0.05 0 0 0</pose>
          <topic>imu</topic>
          <update_rate>100</update_rate>
          <always_on>1</always_on>
          <visualize>false</visualize>
          <imu>
            <angular_velocity>
              <x>
                <noise type='gaussian'>
                  <mean>0.0</mean>
                  <stddev>0.009</stddev>
                </noise>
              </x>
              <y>
                <noise type='gaussian'>
                  <mean>0.0</mean>
                  <stddev>0.009</stddev>
                </noise>
              </y>
              <z>
                <noise type='gaussian'>
                  <mean>0.0</mean>
                  <stddev>0.009</stddev>
                </noise>
              </z>
            </angular_velocity>
            <linear_acceleration>
              <x>
                <noise type='gaussian'>
                  <mean>0.0</mean>
                  <stddev>0.021</stddev>
                </noise>
              </x>
              <y>
                <noise type='gaussian'>
                  <mean>0.0</mean>
                  <stddev>0.021</stddev>
                </noise>
              </y>
              <z>
                <noise type='gaussian'>
                  <mean>0.0</mean>
                  <stddev>0.021</stddev>
                </noise>
              </z>
            </linear_acceleration>
          </imu>
        </sensor>

      </link>

      <link name='left_wheel'>
        <pose relative_to='chassis'>0 0.15 -0.0445 -1.5707 0 0</pose>
        <inertial>
          <mass>0.5</mass>
          <inertia>
            <ixx>0.001</ixx><ixy>0</ixy><ixz>0</ixz>
            <iyy>0.001</iyy><iyz>0</iyz>
            <izz>0.002</izz>
          </inertia>
        </inertial>
        <visual name='visual'>
          <geometry>
            <cylinder>
              <radius>0.078</radius>
              <length>0.05</length>
            </cylinder>
          </geometry>
          <material>
            <ambient>0.1 0.1 0.1 1</ambient>
            <diffuse>0.1 0.1 0.1 1</diffuse>
          </material>
        </visual>
        <collision name='collision'>
          <geometry>
            <cylinder>
              <radius>0.078</radius>
              <length>0.05</length>
            </cylinder>
          </geometry>
        </collision>
      </link>

      <link name='right_wheel'>
        <pose relative_to='chassis'>0 -0.15 -0.0445 -1.5707 0 0</pose>
        <inertial>
          <mass>1.0</mass>
          <inertia>
            <ixx>0.043</ixx><ixy>0</ixy><ixz>0</ixz>
            <iyy>0.043</iyy><iyz>0</iyz>
            <izz>0.08</izz>
          </inertia>
        </inertial>
        <visual name='visual'>
          <geometry>
            <cylinder>
              <radius>0.078</radius>
              <length>0.05</length>
            </cylinder>
          </geometry>
          <material>
            <ambient>0.1 0.1 0.1 1</ambient>
            <diffuse>0.1 0.1 0.1 1</diffuse>
          </material>
        </visual>
        <collision name='collision'>
          <geometry>
            <cylinder>
              <radius>0.078</radius>
              <length>0.05</length>
            </cylinder>
          </geometry>
        </collision>
      </link>

      <joint name='left_wheel_joint' type='revolute'>
        <parent>chassis</parent>
        <child>left_wheel</child>
        <axis>
          <xyz expressed_in='__model__'>0 1 0</xyz>
          <limit>
            <lower>-1.79769e+308</lower>
            <upper>1.79769e+308</upper>
          </limit>
        </axis>
      </joint>

      <joint name='right_wheel_joint' type='revolute'>
        <parent>chassis</parent>
        <child>right_wheel</child>
        <axis>
          <xyz expressed_in='__model__'>0 1 0</xyz>
          <limit>
            <lower>-1.79769e+308</lower>
            <upper>1.79769e+308</upper>
          </limit>
        </axis>
      </joint>

    </model>

    <model name='default_ground'>
      <static>true</static>
      <link name='link'>
        <collision name='collision'>
          <geometry>
            <plane>
              <normal>0 0 1</normal>
              <size>100 100</size>
            </plane>
          </geometry>
        </collision>
      </link>
    </model>

    <!-- Dinding Depan -->
    <model name='wall_front'>
      <static>true</static>
      <pose>3 0 0.5 0 0 -1.5707</pose>
      <link name='link'>
        <collision name='collision'>
          <geometry><box><size>6 0.1 1</size></box></geometry>
        </collision>
        <visual name='visual'>
          <geometry><box><size>6 0.1 1</size></box></geometry>
          <material>
            <ambient>0.8 0.8 0.8 1</ambient>
            <diffuse>0.8 0.8 0.8 1</diffuse>
          </material>
        </visual>
      </link>
    </model>

    <!-- Dinding Belakang -->
    <model name='wall_back'>
      <static>true</static>
      <pose>-3 0 0.5 0 0 -1.5707</pose>
      <link name='link'>
        <collision name='collision'>
          <geometry><box><size>6 0.1 1</size></box></geometry>
        </collision>
        <visual name='visual'>
          <geometry><box><size>6 0.1 1</size></box></geometry>
          <material>
            <ambient>0.8 0.8 0.8 1</ambient>
            <diffuse>0.8 0.8 0.8 1</diffuse>
          </material>
        </visual>
      </link>
    </model>

    <!-- Dinding Kiri -->
    <model name='wall_left'>
      <static>true</static>
      <pose>0 3 0.5 0 0 -1.5707</pose>
      <link name='link'>
        <collision name='collision'>
          <geometry><box><size>0.1 6 1</size></box></geometry>
        </collision>
        <visual name='visual'>
          <geometry><box><size>0.1 6 1</size></box></geometry>
          <material>
            <ambient>0.8 0.8 0.8 1</ambient>
            <diffuse>0.8 0.8 0.8 1</diffuse>
          </material>
        </visual>
      </link>
    </model>

    <!-- Dinding Kanan -->
    <model name='wall_right'>
      <static>true</static>
      <pose>0 -3 0.5 0 0 1.5707</pose>
      <link name='link'>
        <collision name='collision'>
          <geometry><box><size>0.1 6 1</size></box></geometry>
        </collision>
        <visual name='visual'>
          <geometry><box><size>0.1 6 1</size></box></geometry>
          <material>
            <ambient>0.8 0.8 0.8 1</ambient>
            <diffuse>0.8 0.8 0.8 1</diffuse>
          </material>
        </visual>
      </link>
    </model>

    <model name='wall_satu'>
      <static>true</static>
      <pose>0 -1.5 0.5 0 0 1.5707</pose>
      <link name='link'>
        <collision name='collision'>
          <geometry><box><size>0.1 3 1</size></box></geometry>
        </collision>
        <visual name='visual'>
          <geometry><box><size>0.1 3 1</size></box></geometry>
          <material>
            <ambient>0.8 0.8 0.8 1</ambient>
            <diffuse>0.8 0.8 0.8 1</diffuse>
          </material>
        </visual>
      </link>
    </model>

    <model name='wall_dua'>
      <static>true</static>
      <pose>0 1.5 0.5 0 0 1.5707</pose>
      <link name='link'>
        <collision name='collision'>
          <geometry><box><size>0.1 3 1</size></box></geometry>
        </collision>
        <visual name='visual'>
          <geometry><box><size>0.1 3 1</size></box></geometry>
          <material>
            <ambient>0.8 0.8 0.8 1</ambient>
            <diffuse>0.8 0.8 0.8 1</diffuse>
          </material>
        </visual>
      </link>
    </model>

    <model name='overhead_camera'>
      <static>true</static>
      <pose>0 0 10 0 1.5708 0</pose>
      <link name='camera_link'>
        <visual name='visual'>
          <geometry>
            <box><size>0.05 0.05 0.05</size></box>
          </geometry>
        </visual>
        <sensor name='overhead_cam' type='camera'>
          <pose>0 0 0 0 0 0</pose>
          <topic>camera/image_raw</topic>
          <update_rate>30</update_rate>
          <always_on>1</always_on>
          <visualize>true</visualize>
          <camera>
            <horizontal_fov>1.047</horizontal_fov>
            <image>
              <width>640</width>
              <height>480</height>
              <format>R8G8B8</format>
            </image>
            <clip>
              <near>0.01</near>
              <far>100</far>
            </clip>
          </camera>
        </sensor>
      </link>
    </model>

    <gravity>0 0 -9.8</gravity>
    <magnetic_field>5.5645e-06 2.28758e-05 -4.23884e-05</magnetic_field>
    <atmosphere type='adiabatic'/>
    <scene>
      <ambient>0.4 0.4 0.4 1</ambient>
      <background>0.7 0.7 0.7 1</background>
      <shadows>true</shadows>
    </scene>
  </world>
</sdf>